Workbook

Sheet Cover
A1: BESS Pipeline Valuation — Develop-and-Flip (RTB) | J1: ↩ Contents
A2: Subtitle | B2: Investor (LP) IRR/MOIC of an illustrative distribution-BESS develop-and-flip fund (NSW/VIC/SA)
A3: Version | B3: v1.0
A4: Author | B4: Portfolio project (independent rebuild of Boman deck claims)
A5: Date | B5: 2026-06-24
A6: Currency / Units | B6: AUD, $ millions ($m)
A7: Active scenario | B7: ='Scenarios'!$B$3
A8: MASTER CHECK | B8: ='Checks'!$B$19
A10: Decision brief
A11: Decision | B11: Whether the family trust should commit as an LP to an (illustrative) develop-and-flip RTB BESS fund, and at what expected return.
A12: Reframe | B12: The fund sells RTB before construction — MERCHANT RISK PASSES TO THE BUYER. The fund's risk is the survival curve (approve→connect→sell) + the RTB price.
A13: Outputs | B13: Investor IRR & MOIC by scenario, First-Chicago expected return, per-pipeline valuation range, sensitivities.
A14: Detail / horizon | B14: Annual, ~2+1-year term, AUD, $m.
A15: Out of scope | B15: Post-sale operating/merchant cash flows, construction (buyer-funded), tax structuring, FX, debt.
A17: Standards followed
B18: FAST / ICAEW / Macabacus / Operis: Inputs→Calcs→Outputs zones; one Timeline; one-row-one-calc; no hardcodes in formulas; CHOOSE scenario switch + live-case row; checks built alongside; colour code (blue input / black formula / green link); INDEX-MATCH not VLOOKUP; IFERROR on division; closed-form IRR (no volatile functions).
A23: Judgement inputs to OWN (review pass)
B24: Discount rate & premium • the THREE scenario success rates (vs the independent ~45%) • RTB $/MW by state (need independent comps) • dev cost per project & abandonment • fees/carry/hurdle • cash-flow profile. Boman's figures are CLAIMS to verify — defend your own.
A29: TO COMPLETE (analyst review pass)
B30: 1. Trace every formula + colour audit; confirm master check = OK; stress the switch in all 3 positions. 2. Replace 🟡 BENCHMARK / Boman-claim inputs with verified independent values (RTB comps, per-state success, dev cost). 3. Stress a downside where RTB prices are 20–30% lower and success ≈ the independent ~45%; confirm capital can be lost.
A35: DISCLAIMER | B35: ILLUSTRATIVE fund built from public benchmark data; an INDEPENDENT rebuild of the Boman deck's CLAIMS (not an endorsement). NOT investment advice. Wholesale-investor context; read the IM. All figures illustrative and must be independently verified. Capital is at risk.

Sheet Contents
A1: Contents
A3: # | B3: Sheet | C3: Purpose
A4: 1 | B4: Cover | C4: Title, decision brief, master check, disclaimer
A5: 2 | B5: Contents | C5: This page
A6: 3 | B6: Change Log | C6: Version history
A7: 4 | B7: Inputs | C7: All assumptions + imported data (blue)
A8: 5 | B8: Timeline | C8: Master timeline (built once)
A9: 6 | B9: Scenarios | C9: Scenarios + switch + live case + weights
A10: 7 | B10: Calc_Survival | C10: PD-style survival curve (independent) + optimism flag
A11: 8 | B11: Calc_Project_rNPV | C11: Per-project risk-adjusted NAV (RTB − dev cost)
A12: 9 | B12: Calc_Fund | C12: Funnel, fees, investor IRR/MOIC (live)
A13: 10 | B13: Returns | C13: Investor IRR/MOIC by scenario, First-Chicago, valuation range
A14: 11 | B14: Calc_CrossChecks | C14: $/MW benchmark, VC method, RTB vs built
A15: 12 | B15: Sensitivity | C15: Investor MOIC grid (success × price)
... A18: 15 | B18: Sources & Glossary | C18: Sources + glossary

Sheet Change Log
A1: Change Log | J1: ↩ Contents
A3: Date | B3: Version | C3: Change | D3: Author
A4: 2026-06-24 | B4: v1.0 | C4: Initial build: survival curve, per-project rNPV, fund funnel + fees, investor IRR/MOIC, First-Chicago, cross-checks, sensitivity, checks, dashboard. | D4: Claude Code (v1 draft)
C5: [Analyst review pass — record changes here]

Sheet Inputs
A1: INPUTS — all model assumptions (blue = input cell) | J1: ↩ Contents
A2: ILLUSTRATIVE develop-and-flip RTB fund. Boman figures are the manager's CLAIMS — verify. Every input traces to a source.
A3: Assumption | C3: Value | D3: Unit | E3: Source | F3: As at | G3: Status | H3: Duration (yrs)
A4: Discount rate (rNPV / cross-checks)
A5: Risk-free rate (RBA 10yr CGS) | C5: 0.04776 | D5: decimal | E5: RBA Statistical Table F2 (Capital Market Yields — 10yr CGS) | F5: 17-Jun-2026 | G5: LIVE
A6: Development risk premium | C6: 0.14 | D6: decimal | E6: Illustrative / Boman claim (see config) | F6: 2026-06-24 | G6: BENCHMARK
A7: Base discount rate | C7: ='Inputs'!$C$5+'Inputs'!$C$6 | D7: decimal
A8: Fund structure & fees (Boman claim — verify in IM)
A9: Committed capital | C9: 25 | D9: $m | E9: Illustrative / Boman claim (see config) | F9: 2026-06-24 | G9: BENCHMARK
A10: Projects target (delivered & sold) | C10: 35 | D10: count | E10: Illustrative / Boman claim (see config) | F10: 2026-06-24 | G10: BENCHMARK
A11: Term | C11: 3 | D11: years | E11: Illustrative / Boman claim (see config) | F11: 2026-06-24 | G11: BENCHMARK
A12: Entry fee (% of committed) | C12: 0.02 | D12: decimal | E12: Illustrative / Boman claim (see config) | F12: 2026-06-24 | G12: BENCHMARK
A13: Management fee (% p.a.) | C13: 0.02 | D13: decimal | E13: Illustrative / Boman claim (see config) | F13: 2026-06-24 | G13: BENCHMARK
A14: Carried interest (%) | C14: 0.2 | D14: decimal | E14: Illustrative / Boman claim (see config) | F14: 2026-06-24 | G14: BENCHMARK
A15: Hurdle / preferred return (%) | C15: 0.08 | D15: decimal | E15: Illustrative / Boman claim (see config) | F15: 2026-06-24 | G15: BENCHMARK
A16: Development cost & funnel attrition
A17: Development cost per project | C17: 0.5 | D17: $m/project | E17: Boman deck (claim ~$500k/project) — verify bottom-up: site+EIA+grid+community+overhead | F17: 2026-06-24 | G17: BENCHMARK
A18: Abandonment fraction (failed projects) | C18: 0.3 | D18: decimal | E18: Illustrative / Boman claim (see config) | F18: 2026-06-24 | G18: BENCHMARK
A19: Build cost CONTEXT (buyer-funded — NOT in margin)
A20: Built-asset cost (context) | C20: 1.8 | D20: $m/MW | E20: CSIRO GenCost-anchored build cost; context only — the buyer (not the fund) funds construction | F20: 2026-06-24 | G20: BENCHMARK
A21: Survival gates (independent — public data)
A22: Gate 1 — Planning approval | C22: 0.8 | D22: prob | E22: NSW Planning Portal — approved vs refused/withdrawn BESS major projects (benchmark) | F22: 2026-06-24 | G22: BENCHMARK | H22: 1.25
A23: Gate 2 — Grid connection | C23: 0.7 | D23: prob | E23: AEMO Connections Scorecard / KCI — connection success rate & duration (benchmark) | F23: 2026-06-24 | G23: BENCHMARK | H23: 1.5
A24: Gate 3 — Reach sale | C24: 0.8 | D24: prob | E24: AEMO proposed->committed attrition + active buyer pool (benchmark) | F24: 2026-06-24 | G24: BENCHMARK | H24: 0.5
A25: RTB exit price — $/MW by state (Boman claim — verify)
A26: NSW | C26: 0.2 | D26: $m/MW | E26: RTB $/MW by state (Boman claim — independent comps needed) | F26: 2026-06-24 | G26: BENCHMARK
A27: VIC | C27: 0.18 | D27: $m/MW | E27: RTB $/MW by state (Boman claim — independent comps needed) | F27: 2026-06-24 | G27: BENCHMARK
A28: SA | C28: 0.12 | D28: $m/MW | E28: RTB $/MW by state (Boman claim — independent comps needed) | F28: 2026-06-24 | G28: BENCHMARK
A29: VC method
A30: VC target return (cross-check) | C30: 0.25 | D30: decimal | E30: Illustrative / Boman claim (see config) | F30: 2026-06-24 | G30: BENCHMARK
A31: Investor cash-flow profile (period 0..3; each sums to 100%)
A32: Capital call profile | C32: 0.5 | D32: 0.5 | E32: 0 | F32: 0
A33: Distribution profile | C33: 0 | D33: 0 | E33: 0.5 | F33: 0.5
A34: Illustrative pipeline (representative ~5 MW distribution projects)
A35: Project | B35: State | C35: Location | D35: MW | E35: Duration (h) | F35: MWh | G35: Years to sale
A36: Riverina 5MW BESS (illustrative) | B36: NSW | C36: Wagga Wagga, NSW | D36: 5 | E36: 2 | F36: =D36*E36 | G36: 2.5
A37: Hunter Edge 5MW BESS (illustrative) | B37: NSW | C37: Hunter Valley, NSW | D37: 5 | E37: 4 | F37: =D37*E37 | G37: 3
A38: Illawarra 5MW BESS (illustrative) | B38: NSW | C38: Wollongong, NSW | D38: 5 | E38: 2 | F38: =D38*E38 | G38: 2
A39: Latrobe 5MW BESS (illustrative) | B39: VIC | C39: Latrobe Valley, VIC | D39: 5 | E39: 2 | F39: =D39*E39 | G39: 2.5
A40: Western Plains 5MW BESS (illustrative) | B40: VIC | C40: Horsham, VIC | D40: 5 | E40: 2 | F40: =D40*E40 | G40: 2
...

Sheet Timeline
A1: TIMELINE — built once; every sheet links here | J1: ↩ Contents
A2: Base year | B2: 2026
A3: Period number | B3: 0 | C3: 1 | D3: 2 | E3: 3
A4: Year | B4: =$B$2+B3 | C4: =$B$2+C3 | D4: =$B$2+D3 | E4: =$B$2+E3
A5: Discount factor @ live discount | B5: =IFERROR(1/(1+'Scenarios'!$E$9)^B3,0) | C5: =IFERROR(1/(1+'Scenarios'!$E$9)^C3,0) | D5: =IFERROR(1/(1+'Scenarios'!$E$9)^D3,0) | E5: =IFERROR(1/(1+'Scenarios'!$E$9)^E3,0)

Sheet Scenarios
A1: SCENARIOS — one switch drives the live case (CHOOSE) | J1: ↩ Contents
A2: Scenario switch (1=Conservative 2=Base 3=Ideal) | B2: 2
A3: Active scenario | B3: =CHOOSE('Scenarios'!$B$2,"Conservative","Base","Ideal")
A4: Driver | B4: Conservative | C4: Base | D4: Ideal | E4: Live (active)
A5: Cumulative success rate | B5: 0.4 | C5: 0.65 | D5: 0.8 | E5: =CHOOSE('Scenarios'!$B$2,B5,C5,D5)
A6: RTB price multiplier | B6: 0.85 | C6: 1 | D6: 1.15 | E6: =CHOOSE('Scenarios'!$B$2,B6,C6,D6)
A7: Dev cost multiplier | B7: 1.05 | C7: 1 | D7: 0.97 | E7: =CHOOSE('Scenarios'!$B$2,B7,C7,D7)
A8: Discount rate override (0=use base) | B8: 0.22 | C8: 0 | D8: 0.16 | E8: =CHOOSE('Scenarios'!$B$2,B8,C8,D8)
A9: Live discount rate | E9: =IF('Scenarios'!$E$8=0,'Inputs'!$C$7,'Scenarios'!$E$8)
A11: First-Chicago weights
B12: Conservative | C12: Base | D12: Ideal | E12: Sum
A13: Weight | B13: 0.3 | C13: 0.5 | D13: 0.2 | E13: =SUM(B13:D13)
A15: Success rates mirror Boman's deck (40/65/80%) for comparability. The INDEPENDENT survival curve (~45%) sits below Base (65%) — see Calc_Survival. Scenarios are the analyst's to OWN.

Sheet Calc_Survival
A1: CALC — PD-STYLE SURVIVAL CURVE (independent, public data) | J1: ↩ Contents
A2: Cumulative P(success) = product of gate probabilities — structurally a multi-period PD / survival curve (the credit-risk bridge). This is the model's INDEPENDENT estimate; the SCENARIOS set the success rate used in valuation.
A3: Gate | B3: Probability | C3: Cumulative survival
A4: Gate 1 — Planning approval | B4: ='Inputs'!$C$22 | C4: =B4
A5: Gate 2 — Grid connection | B5: ='Inputs'!$C$23 | C5: =C4*B5
A6: Gate 3 — Reach sale | B6: ='Inputs'!$C$24 | C6: =C5*B6
A7: Independent cumulative P(success) | C7: =C6
A9: Base scenario success (Boman claim) | C9: ='Scenarios'!$C$5
A10: Optimism gap (Base − independent) | C10: =C9-'Calc_Survival'!$C$7
C11: =IF(C10>0.05,"FLAG: Base optimistic","ok")
A12: Independent ~45% sits BELOW Boman's Base (65%): treat Base as optimistic; ask for sub-5MW, per-state evidence. The sub-5MW AEMO registration exemption MAY lift small-distribution success above the large-project benchmark — verify.

Sheet Calc_Project_rNPV
A1: CALC — PER-PROJECT RISK-ADJUSTED NAV (rNPV) | J1: ↩ Contents
A2: Per project: RTB sale − DEVELOPMENT cost = margin → × cumulative success → discounted. Cost is DEV ONLY (the fund sells RTB; the buyer funds construction). All figures AUD $m unless stated.
A3: Project | B3: State | C3: MW | D3: Years | E3: RTB $/MW | F3: Sale mult | G3: Sale $m | H3: Dev cost $m | I3: Margin $m | J3: Cum P | K3: Risk-adj $m | L3: Disc factor | M3: PV $m | N3: Sale@1x $m
A4: ='Inputs'!$A$36 | B4: ='Inputs'!$B$36 | C4: ='Inputs'!$D$36 | D4: ='Inputs'!$G$36 | E4: =IFERROR(INDEX('Inputs'!$C$26:$C$28,MATCH(B4,'Inputs'!$A$26:$A$28,0)),0) | F4: ='Scenarios'!$E$6 | G4: =C4*E4*F4 | H4: ='Inputs'!$C$17*'Scenarios'!$E$7 | I4: =G4-H4 | J4: ='Scenarios'!$E$5 | K4: =I4*J4 | L4: =IFERROR(1/(1+'Scenarios'!$E$9)^D4,0) | M4: =K4*L4 | N4: =C4*E4
A5: ='Inputs'!$A$37 | B5: ='Inputs'!$B$37 | C5: ='Inputs'!$D$37 | D5: ='Inputs'!$G$37 | E5: =IFERROR(INDEX('Inputs'!$C$26:$C$28,MATCH(B5,'Inputs'!$A$26:$A$28,0)),0) | F5: ='Scenarios'!$E$6 | G5: =C5*E5*F5 | H5: ='Inputs'!$C$17*'Scenarios'!$E$7 | I5: =G5-H5 | J5: ='Scenarios'!$E$5 | K5: =I5*J5 | L5: =IFERROR(1/(1+'Scenarios'!$E$9)^D5,0) | M5: =K5*L5 | N5: =C5*E5
A6: ='Inputs'!$A$38 | B6: ='Inputs'!$B$38 | C6: ='Inputs'!$D$38 | D6: ='Inputs'!$G$38 | E6: =IFERROR(INDEX('Inputs'!$C$26:$C$28,MATCH(B6,'Inputs'!$A$26:$A$28,0)),0) | F6: ='Scenarios'!$E$6 | G6: =C6*E6*F6 | H6: ='Inputs'!$C$17*'Scenarios'!$E$7 | I6: =G6-H6 | J6: ='Scenarios'!$E$5 | K6: =I6*J6 | L6: =IFERROR(1/(1+'Scenarios'!$E$9)^D6,0) | M6: =K6*L6 | N6: =C6*E6
A7: ='Inputs'!$A$39 | B7: ='Inputs'!$B$39 | C7: ='Inputs'!$D$39 | D7: ='Inputs'!$G$39 | E7: =IFERROR(INDEX('Inputs'!$C$26:$C$28,MATCH(B7,'Inputs'!$A$26:$A$28,0)),0) | F7: ='Scenarios'!$E$6 | G7: =C7*E7*F7 | H7: ='Inputs'!$C$17*'Scenarios'!$E$7 | I7: =G7-H7 | J7: ='Scenarios'!$E$5 | K7: =I7*J7 | L7: =IFERROR(1/(1+'Scenarios'!$E$9)^D7,0) | M7: =K7*L7 | N7: =C7*E7
A8: ='Inputs'!$A$40 | B8: ='Inputs'!$B$40 | C8: ='Inputs'!$D$40 | D8: ='Inputs'!$G$40 | E8: =IFERROR(INDEX('Inputs'!$C$26:$C$28,MATCH(B8,'Inputs'!$A$26:$A$28,0)),0) | F8: ='Scenarios'!$E$6 | G8: =C8*E8*F8 | H8: ='Inputs'!$C$17*'Scenarios'!$E$7 | I8: =G8-H8 | J8: ='Scenarios'!$E$5 | K8: =I8*J8 | L8: =IFERROR(1/(1+'Scenarios'!$E$9)^D8,0) | M8: =K8*L8 | N8: =C8*E8
A9: ='Inputs'!$A$41 | B9: ='Inputs'!$B$41 | C9: ='Inputs'!$D$41 | D9: ='Inputs'!$G$41 | E9: =IFERROR(INDEX('Inputs'!$C$26:$C$28,MATCH(B9,'Inputs'!$A$26:$A$28,0)),0) | F9: ='Scenarios'!$E$6 | G9: =C9*E9*F9 | H9: ='Inputs'!$C$17*'Scenarios'!$E$7 | I9: =G9-H9 | J9: ='Scenarios'!$E$5 | K9: =I9*J9 | L9: =IFERROR(1/(1+'Scenarios'!$E$9)^D9,0) | M9: =K9*L9 | N9: =C9*E9
A10: Pipeline total (representative) | C10: =SUM(C4:C9) | G10: =SUM(G4:G9) | H10: =SUM(H4:H9) | M10: =SUM(M4:M9)
A11: Blended RTB sale per project (@1x) | M11: =AVERAGE('Calc_Project_rNPV'!$N$4:$N$9)

Sheet Calc_Fund
A1: CALC — FUND FUNNEL, FEES & INVESTOR RETURN (live scenario) | J1: ↩ Contents
A2: The funnel: projects_started = target ÷ success (widens as success falls). Full dev cost on delivered + partial on dropouts. Fees: entry + management + carry over the hurdle. Investor IRR is closed-form over the effective hold (so it reproduces in any Excel). All figures AUD $m.
A4: Funnel (live scenario)
A5: Live cumulative success | C5: ='Scenarios'!$E$5
A6: Projects target (delivered & sold) | C6: ='Inputs'!$C$10
A7: Projects started (funnel) | C7: =IFERROR(C6/C5,0)
A8: Projects failed (dropouts) | C8: =C7-C6
A9: Dev cost per project (live) | C9: ='Inputs'!$C$17*'Scenarios'!$E$7
A10: Total development cost | C10: =C6*C9+C8*'Inputs'!$C$18*C9
A11: Proceeds & fees
A12: Blended RTB sale per project (live) | C12: ='Calc_Project_rNPV'!$M$11*'Scenarios'!$E$6
A13: Gross proceeds | C13: =C6*C12
A14: Entry fee | C14: ='Inputs'!$C$12*'Inputs'!$C$9
A15: Management fee (total) | C15: ='Inputs'!$C$13*'Inputs'!$C$9*'Inputs'!$C$11
A16: Invested capital (LP, called) | C16: =C10+C14+C15
A17: Carry, distributions & return (live)
A18: Profit before carry | C18: =C13-C16
A19: Hurdle factor = (1+hurdle)^term − 1 | C19: =(1+'Inputs'!$C$15)^'Inputs'!$C$11-1
A20: Hurdle amount | C20: =C16*C19
A21: Carry to GP | C21: ='Inputs'!$C$14*MAX(0,C18-C20)
A22: Distributions to LP | C22: =C13-C21
A23: MOIC (net) | C23: =IFERROR(C22/C16,0)
A24: Mean distribution period (yrs) | C24: =SUMPRODUCT('Timeline'!$B$3:$E$3,'Inputs'!$C$33:$F$33)
A25: Mean capital-call period (yrs) | C25: =SUMPRODUCT('Timeline'!$B$3:$E$3,'Inputs'!$C$32:$F$32)
A26: Effective hold (yrs) | C26: =C24-C25
A27: Investor IRR (live, closed-form) | C27: =IFERROR(C23^(1/C26)-1,0)

Sheet Returns
A1: RETURNS — investor IRR & MOIC by scenario, First-Chicago, valuation range | J1: ↩ Contents
A2: Each scenario's funnel is computed independently of the switch. Investor IRR is closed-form over the effective hold. All figures AUD $m unless stated.
A3: Investor return by scenario (after fees)
A4: Metric | B4: Conservative | C4: Base | D4: Ideal
A5: Cumulative success | B5: ='Scenarios'!$B$5 | C5: ='Scenarios'!$C$5 | D5: ='Scenarios'!$D$5
A6: RTB price multiplier | B6: ='Scenarios'!$B$6 | C6: ='Scenarios'!$C$6 | D6: ='Scenarios'!$D$6
A7: Dev cost multiplier | B7: ='Scenarios'!$B$7 | C7: ='Scenarios'!$C$7 | D7: ='Scenarios'!$D$7
A8: Dev cost per project | B8: ='Inputs'!$C$17*B7 | C8: ='Inputs'!$C$17*C7 | D8: ='Inputs'!$C$17*D7
A9: Projects started | B9: =IFERROR('Inputs'!$C$10/B5,0) | C9: =IFERROR('Inputs'!$C$10/C5,0) | D9: =IFERROR('Inputs'!$C$10/D5,0)
A10: Projects failed | B10: =B9-'Inputs'!$C$10 | C10: =C9-'Inputs'!$C$10 | D10: =D9-'Inputs'!$C$10
A11: Total dev cost | B11: ='Inputs'!$C$10*B8+B10*'Inputs'!$C$18*B8 | C11: ='Inputs'!$C$10*C8+C10*'Inputs'!$C$18*C8 | D11: ='Inputs'!$C$10*D8+D10*'Inputs'!$C$18*D8
A12: Gross proceeds | B12: ='Inputs'!$C$10*'Calc_Project_rNPV'!$M$11*B6 | C12: ='Inputs'!$C$10*'Calc_Project_rNPV'!$M$11*C6 | D12: ='Inputs'!$C$10*'Calc_Project_rNPV'!$M$11*D6
A13: Invested capital | B13: =B11+'Calc_Fund'!$C$15+'Calc_Fund'!$C$14 | C13: =C11+'Calc_Fund'!$C$15+'Calc_Fund'!$C$14 | D13: =D11+'Calc_Fund'!$C$15+'Calc_Fund'!$C$14
A14: Profit before carry | B14: =B12-B13 | C14: =C12-C13 | D14: =D12-D13
A15: Hurdle amount | B15: =B13*'Calc_Fund'!$C$19 | C15: =C13*'Calc_Fund'!$C$19 | D15: =D13*'Calc_Fund'!$C$19
A16: Carry to GP | B16: ='Inputs'!$C$14*MAX(0,B14-B15) | C16: ='Inputs'!$C$14*MAX(0,C14-C15) | D16: ='Inputs'!$C$14*MAX(0,D14-D15)
A17: Distributions to LP | B17: =B12-B16 | C17: =C12-C16 | D17: =D12-D16
A18: MOIC (net) | B18: =IFERROR(B17/B13,0) | C18: =IFERROR(C17/C13,0) | D18: =IFERROR(D17/D13,0)
A19: Investor IRR | B19: =IFERROR(B18^(1/'Calc_Fund'!$C$26)-1,0) | C19: =IFERROR(C18^(1/'Calc_Fund'!$C$26)-1,0) | D19: =IFERROR(D18^(1/'Calc_Fund'!$C$26)-1,0)
A21: First-Chicago probability-weighted expected return
B22: Conservative | C22: Base | D22: Ideal | E22: Expected
A23: Weight | B23: ='Scenarios'!$B$13 | C23: ='Scenarios'!$C$13 | D23: ='Scenarios'!$D$13
A24: Investor IRR | B24: ='Returns'!$B$19 | C24: ='Returns'!$C$19 | D24: ='Returns'!$D$19 | E24: =SUMPRODUCT('Scenarios'!$B$13:$D$13,B24:D24)
A25: MOIC (net) | B25: ='Returns'!$B$18 | C25: ='Returns'!$C$18 | D25: ='Returns'!$D$18 | E25: =SUMPRODUCT('Scenarios'!$B$13:$D$13,B25:D25)
A27: Valuation range (per-pipeline asset value — cross-check) | C27: Representative 6-project pipeline, NOT the whole fund.
A28: rNPV pipeline (Base) | C28: ='Calc_Project_rNPV'!$M$10
A29: $/MW benchmark (dev value) | C29: ='Calc_CrossChecks'!$C$9
A30: VC method (today value) | C30: ='Calc_CrossChecks'!$C$18
A31: Low | C31: =MIN(C28:C30)
A32: Midpoint | C32: =AVERAGE(C28:C30)
A33: High | C33: =MAX(C28:C30)

Sheet Calc_CrossChecks
A1: CALC — CROSS-CHECKS: $/MW benchmark, VC method, RTB vs built | J1: ↩ Contents
A2: Asset-value cross-checks on the representative pipeline, Base scenario. All figures AUD $m unless stated.
A3: $/MW benchmark (Base)
A4: Total pipeline MW | C4: =SUM('Calc_Project_rNPV'!$C$4:$C$9)
A5: Gross RTB asset value $m | C5: =SUMPRODUCT('Calc_Project_rNPV'!$C$4:$C$9,'Calc_Project_rNPV'!$E$4:$E$9)*'Scenarios'!$C$6
A6: Total dev cost $m | C6: ='Inputs'!$C$17*'Scenarios'!$C$7*6
A7: Average years to sale | C7: =AVERAGE('Calc_Project_rNPV'!$D$4:$D$9)
A8: Cumulative success (Base) | C8: ='Scenarios'!$C$5
A9: $/MW implied dev value $m | C9: =IFERROR((C5-C6)*C8/(1+'Inputs'!$C$7)^C7,0)
A11: VC method (Base)
A12: Total RTB sale value $m | C12: =SUMPRODUCT('Calc_Project_rNPV'!$C$4:$C$9,'Calc_Project_rNPV'!$E$4:$E$9)*'Scenarios'!$C$6
A13: Total dev cost $m | C13: =C6
A14: Cumulative success (Base) | C14: =C8
A15: Exit equity value (expected) $m | C15: =C14*(C12-C13)
A16: VC target return | C16: ='Inputs'!$C$30
A17: Hold horizon (yrs) | C17: ='Inputs'!$C$11
A18: VC today value $m | C18: =IFERROR(C15/(1+C16)^C17,0)
A20: RTB as % of built-asset value (sense-check)
A21: State | B21: RTB $/MW | C21: Built $/MW | D21: RTB % of built
A22: NSW | B22: ='Inputs'!$C$26 | C22: ='Inputs'!$C$20 | D22: =IFERROR(B22/C22,0)
A23: VIC | B23: ='Inputs'!$C$27 | C23: ='Inputs'!$C$20 | D23: =IFERROR(B23/C23,0)
A24: SA | B24: ='Inputs'!$C$28 | C24: ='Inputs'!$C$20 | D24: =IFERROR(B24/C24,0)
A25: Expect ~10–12% — confirms RTB is the early-stage development slice, not the built asset.

Sheet Sensitivity
A1: SENSITIVITY — investor MOIC (net): success × RTB price | J1: ↩ Contents
A2: Investor MOIC vs cumulative success (down) × RTB price multiplier (across); all else at Base. IRR ≈ MOIC^(1/eff-hold). Live formula grid (recalculates everywhere). All figures AUD $m / x.
A4: Carry % | B4: ='Inputs'!$C$14
A5: Hurdle factor | B5: ='Calc_Fund'!$C$19
A6: Fixed fees (mgmt+entry) $m | B6: ='Calc_Fund'!$C$15+'Calc_Fund'!$C$14
B8: Price mult → | C8: 0.7 | D8: 0.85 | E8: 1 | F8: 1.15 | G8: 1.3
B9: Gross $m → | C9: ='Inputs'!$C$10*'Calc_Project_rNPV'!$M$11*C8 | D9: ='Inputs'!$C$10*'Calc_Project_rNPV'!$M$11*D8 | E9: ='Inputs'!$C$10*'Calc_Project_rNPV'!$M$11*E8 | F9: ='Inputs'!$C$10*'Calc_Project_rNPV'!$M$11*F8 | G9: ='Inputs'!$C$10*'Calc_Project_rNPV'!$M$11*G8
B10: Success ↓ | C10: MOIC | D10: MOIC | E10: MOIC | F10: MOIC | G10: MOIC | H10: Started | I10: Total dev | J10: Invested
B11: 0.35 | C11: =IFERROR((C$9-'Sensitivity'!$B$4*MAX(0,(C$9-$J11)-$J11*'Sensitivity'!$B$5))/$J11,0) | D11: =IFERROR((D$9-'Sensitivity'!$B$4*MAX(0,(D$9-$J11)-$J11*'Sensitivity'!$B$5))/$J11,0) | E11: =IFERROR((E$9-'Sensitivity'!$B$4*MAX(0,(E$9-$J11)-$J11*'Sensitivity'!$B$5))/$J11,0) | F11: =IFERROR((F$9-'Sensitivity'!$B$4*MAX(0,(F$9-$J11)-$J11*'Sensitivity'!$B$5))/$J11,0) | G11: =IFERROR((G$9-'Sensitivity'!$B$4*MAX(0,(G$9-$J11)-$J11*'Sensitivity'!$B$5))/$J11,0) | H11: =IFERROR('Inputs'!$C$10/$B11,0) | I11: ='Inputs'!$C$10*'Inputs'!$C$17+(H11-'Inputs'!$C$10)*'Inputs'!$C$18*'Inputs'!$C$17 | J11: =I11+'Sensitivity'!$B$6
B12: 0.45 | C12: =IFERROR((C$9-'Sensitivity'!$B$4*MAX(0,(C$9-$J12)-$J12*'Sensitivity'!$B$5))/$J12,0) | D12: =IFERROR((D$9-'Sensitivity'!$B$4*MAX(0,(D$9-$J12)-$J12*'Sensitivity'!$B$5))/$J12,0) | E12: =IFERROR((E$9-'Sensitivity'!$B$4*MAX(0,(E$9-$J12)-$J12*'Sensitivity'!$B$5))/$J12,0) | F12: =IFERROR((F$9-'Sensitivity'!$B$4*MAX(0,(F$9-$J12)-$J12*'Sensitivity'!$B$5))/$J12,0) | G12: =IFERROR((G$9-'Sensitivity'!$B$4*MAX(0,(G$9-$J12)-$J12*'Sensitivity'!$B$5))/$J12,0) | H12: =IFERROR('Inputs'!$C$10/$B12,0) | I12: ='Inputs'!$C$10*'Inputs'!$C$17+(H12-'Inputs'!$C$10)*'Inputs'!$C$18*'Inputs'!$C$17 | J12: =I12+'Sensitivity'!$B$6
B13: 0.55 | C13: =IFERROR((C$9-'Sensitivity'!$B$4*MAX(0,(C$9-$J13)-$J13*'Sensitivity'!$B$5))/$J13,0) | D13: =IFERROR((D$9-'Sensitivity'!$B$4*MAX(0,(D$9-$J13)-$J13*'Sensitivity'!$B$5))/$J13,0) | E13: =IFERROR((E$9-'Sensitivity'!$B$4*MAX(0,(E$9-$J13)-$J13*'Sensitivity'!$B$5))/$J13,0) | F13: =IFERROR((F$9-'Sensitivity'!$B$4*MAX(0,(F$9-$J13)-$J13*'Sensitivity'!$B$5))/$J13,0) | G13: =IFERROR((G$9-'Sensitivity'!$B$4*MAX(0,(G$9-$J13)-$J13*'Sensitivity'!$B$5))/$J13,0) | H13: =IFERROR('Inputs'!$C$10/$B13,0) | I13: ='Inputs'!$C$10*'Inputs'!$C$17+(H13-'Inputs'!$C$10)*'Inputs'!$C$18*'Inputs'!$C$17 | J13: =I13+'Sensitivity'!$B$6
B14: 0.65 | C14: =IFERROR((C$9-'Sensitivity'!$B$4*MAX(0,(C$9-$J14)-$J14*'Sensitivity'!$B$5))/$J14,0) | D14: =IFERROR((D$9-'Sensitivity'!$B$4*MAX(0,(D$9-$J14)-$J14*'Sensitivity'!$B$5))/$J14,0) | E14: =IFERROR((E$9-'Sensitivity'!$B$4*MAX(0,(E$9-$J14)-$J14*'Sensitivity'!$B$5))/$J14,0) | F14: =IFERROR((F$9-'Sensitivity'!$B$4*MAX(0,(F$9-$J14)-$J14*'Sensitivity'!$B$5))/$J14,0) | G14: =IFERROR((G$9-'Sensitivity'!$B$4*MAX(0,(G$9-$J14)-$J14*'Sensitivity'!$B$5))/$J14,0) | H14: =IFERROR('Inputs'!$C$10/$B14,0) | I14: ='Inputs'!$C$10*'Inputs'!$C$17+(H14-'Inputs'!$C$10)*'Inputs'!$C$18*'Inputs'!$C$17 | J14: =I14+'Sensitivity'!$B$6
B15: 0.8 | C15: =IFERROR((C$9-'Sensitivity'!$B$4*MAX(0,(C$9-$J15)-$J15*'Sensitivity'!$B$5))/$J15,0) | D15: =IFERROR((D$9-'Sensitivity'!$B$4*MAX(0,(D$9-$J15)-$J15*'Sensitivity'!$B$5))/$J15,0) | E15: =IFERROR((E$9-'Sensitivity'!$B$4*MAX(0,(E$9-$J15)-$J15*'Sensitivity'!$B$5))/$J15,0) | F15: =IFERROR((F$9-'Sensitivity'!$B$4*MAX(0,(F$9-$J15)-$J15*'Sensitivity'!$B$5))/$J15,0) | G15: =IFERROR((G$9-'Sensitivity'!$B$4*MAX(0,(G$9-$J15)-$J15*'Sensitivity'!$B$5))/$J15,0) | H15: =IFERROR('Inputs'!$C$10/$B15,0) | I15: ='Inputs'!$C$10*'Inputs'!$C$17+(H15-'Inputs'!$C$10)*'Inputs'!$C$18*'Inputs'!$C$17 | J15: =I15+'Sensitivity'!$B$6

Sheet Checks
A1: CHECKS — integrity framework (master check feeds the Cover) | J1: ↩ Contents
A3: Check | B3: Result | C3: Note
A4: Every gate probability ∈ [0,1] | B4: =IF(AND(MIN('Inputs'!$C$22:$C$24)>=0,MAX('Inputs'!$C$22:$C$24)<=1),"OK","ERROR") | C4: Gate probs bounded
A5: Independent cumulative ≤ each gate | B5: =IF('Calc_Survival'!$C$7<=MIN('Calc_Survival'!$B$4:$B$6)+0.000001,"OK","ERROR") | C5: Survival monotonic
A6: All MW positive | B6: =IF(MIN('Inputs'!$D$36:$D$41)>0,"OK","ERROR") | C6: Sign check
A7: All RTB sale values positive | B7: =IF(MIN('Calc_Project_rNPV'!$G$4:$G$9)>0,"OK","ERROR") | C7: Sign check
A8: Dev cost positive | B8: =IF('Inputs'!$C$17>0,"OK","ERROR") | C8: Sign check
A9: Scenario switch ∈ {1,2,3} | B9: =IF(AND('Scenarios'!$B$2>=1,'Scenarios'!$B$2<=3),"OK","ERROR") | C9: Switch valid
A10: Scenario success monotonic | B10: =IF(AND('Scenarios'!$B$5<='Scenarios'!$C$5,'Scenarios'!$C$5<='Scenarios'!$D$5),"OK","ERROR") | C10: Cons ≤ Base ≤ Ideal
A11: Investor IRR monotonic | B11: =IF(AND('Returns'!$B$19<='Returns'!$C$19,'Returns'!$C$19<='Returns'!$D$19),"OK","ERROR") | C11: Cons ≤ Base ≤ Ideal
A12: Scenario weights sum to 100% | B12: =IF(ABS('Scenarios'!$E$13-1)<0.001,"OK","ERROR") | C12: First-Chicago weights
A13: Capital-call profile sums to 100% | B13: =IF(ABS(SUM('Inputs'!$C$32:$F$32)-1)<0.001,"OK","ERROR") | C13: Cash-flow profile
A14: Distribution profile sums to 100% | B14: =IF(ABS(SUM('Inputs'!$C$33:$F$33)-1)<0.001,"OK","ERROR") | C14: Cash-flow profile
A15: First-Chicago IRR within scenario range | B15: =IF(AND(G15>=E15-0.0001,G15<=F15+0.0001),"OK","ERROR") | C15: Weighting sanity (helpers E:G) | E15: =MIN('Returns'!$B$19:$D$19) | F15: =MAX('Returns'!$B$19:$D$19) | G15: ='Returns'!$E$24
A16: Invested capital positive (all scenarios) | B16: =IF(MIN('Returns'!$B$13:$D$13)>0,"OK","ERROR") | C16: Sign check
A17: No error cells in key outputs | B17: =IF(SUM(E17:G17)=0,"OK","ERROR") | C17: #REF!/#DIV0! scan | E17: =SUMPRODUCT(--ISERROR('Calc_Project_rNPV'!$M$4:$M$10)) | F17: =SUMPRODUCT(--ISERROR('Returns'!$B$19:$D$19)) | G17: =SUMPRODUCT(--ISERROR('Sensitivity'!$C$11:$G$15))
A19: MASTER CHECK | B19: =IF(COUNTIF(B4:B17,"ERROR")=0,"OK","ERROR")

Sheet Dashboard
A1: ILLUSTRATIVE DISTRIBUTION-BESS DEVELOP-AND-FLIP FUND — DASHBOARD | J1: ↩ Contents
A2: Develop ~5 MW distribution BESS to RTB, sell before construction (NSW/VIC/SA). ILLUSTRATIVE — Boman figures are manager claims to verify. Not investment advice.
A4: Active scenario | B4: ='Scenarios'!$B$3 | D4: Master check | E4: ='Checks'!$B$19
A6: EXPECTED INVESTOR RETURN (First-Chicago) | D6: LIVE SCENARIO
A7: Expected IRR (after fees) | B7: ='Returns'!$E$24 | D7: Investor IRR (live) | E7: ='Calc_Fund'!$C$27
A8: Expected MOIC | B8: ='Returns'!$E$25 | D8: MOIC (live) | E8: ='Calc_Fund'!$C$23
A10: INVESTOR IRR BY SCENARIO | D10: KEY ASSUMPTIONS & FLAG
A11: Scenario | B11: Success | C11: IRR | D11: Committed capital $m | E11: ='Inputs'!$C$9
A12: Conservative | B12: ='Scenarios'!$B$5 | C12: ='Returns'!$B$19 | D12: Projects target | E12: ='Inputs'!$C$10
A13: Base | B13: ='Scenarios'!$C$5 | C13: ='Returns'!$C$19 | D13: Independent cum P(success) | E13: ='Calc_Survival'!$C$7
A14: Ideal | B14: ='Scenarios'!$D$5 | C14: ='Returns'!$D$19 | D14: Base scenario success | E14: ='Scenarios'!$C$5
D15: Optimism gap (Base − indep.) | E15: ='Calc_Survival'!$C$10
A17: Conclusion (illustrative)
A18: A real, policy-backed, capital-light niche with a viable RTB exit — but conditional. Merchant risk passes to the buyer; the fund's risk is the survival curve + the RTB price. The independent success (~45%) sits BELOW Boman's Base (65%), and the Conservative case can lose capital. The single biggest risk is EXIT/BUYER risk (non-binding buyers; RTB stage), then development/approval risk. Pursue only on verified buyer depth, RTB comps, and a survivable downside.

Sheet Sources & Glossary
A1: Sources & Glossary | J1: ↩ Contents
A3: Sources (LIVE = fetched; BENCHMARK = documented public benchmark / Boman claim, verify)
A4: Input | B4: Status | C4: As at | D4: Source
A5: Risk-free rate (RBA 10yr CGS) | B5: LIVE | C5: 17-Jun-2026 | D5: RBA Statistical Table F2 (Capital Market Yields — 10yr CGS)
A6: Built-cost context (CSIRO GenCost) | B6: BENCHMARK | C6: 2026-06-24 | D6: CSIRO GenCost-anchored build cost; context only — the buyer (not the fund) funds construction
A7: Dev cost per project | B7: BENCHMARK | C7: 2026-06-24 | D7: Boman deck (claim ~$500k/project) — verify bottom-up: site+EIA+grid+community+overhead
A8: Planning approval prob (planning portals) | B8: BENCHMARK | C8: 2026-06-24 | D8: NSW Planning Portal — approved vs refused/withdrawn BESS major projects (benchmark)
A9: Grid connection prob (AEMO) | B9: BENCHMARK | C9: 2026-06-24 | D9: AEMO Connections Scorecard / KCI — connection success rate & duration (benchmark)
A10: Reach-sale prob (buyer pool / AEMO attrition) | B10: BENCHMARK | C10: 2026-06-24 | D10: AEMO proposed->committed attrition + active buyer pool (benchmark)
A11: RTB $/MW by state (Boman claim) | B11: BENCHMARK | C11: 2026-06-24 | D11: RTB $/MW by state (Boman claim — independent comps needed)
A13: RTB comps: publicly reported deals only; paid DBs (BNEF, Enerdatics, Mergermarket) out of scope. Boman's prices are claims to verify.
A15: Glossary
A16: RTB | D16: Ready-to-build / development rights — a shovel-ready project sold before construction.
A17: rNPV | D17: Risk-adjusted NPV — each cash flow × probability of occurring, then discounted.
A18: Survival curve / PD | D18: Cumulative probability a project clears all gates; structurally a multi-period probability-of-default curve.
A19: Funnel | D19: projects_started = target ÷ success; you fund dev cost on every started project (full on delivered, partial on dropouts).
A20: Carry / hurdle | D20: GP carried interest (20%) earned only on profit above the LP preferred return (8%).
A21: MOIC / IRR | D21: Multiple on invested capital; annualised return (closed-form over the effective hold).
A22: First Chicago | D22: Probability-weight the scenario returns into a single expected return.
A23: Develop-and-flip | D23: Develop, de-risk, then sell RTB — the margin is the value uplift; merchant risk passes to the buyer.
